<?xml version="1.0" ?>
<robot name="seven_dof_arm" xmlns:xacro="http://ros.org/wiki/xacro">


  <material name = "Black">
    <color rgba = "0.0 0.0 0.0 1.0"/>
  </material>


  <material name = "Red">
    <color rgba = "0.8 0.0 0.0 1.0"/>
  </material>

  <material name = "White">
    <color rgba = "1.0 1.0 1.0 1.0"/>
  </material>

  <!-- Bottom Link  -->
  <link name = "bottom_link">
    <visual>
      <origin xyz = "0 0 0.01" rpy = "0 0 0"/>
      <geometry>
       <box size = "1 1 0.02"/>
      </geometry>
      <material name = "White"/>
    </visual>

    <collision>
      <origin xyz = "0 0 0.01" rpy = "0 0 0"/>
      <geometry>
        <box size = "1 1 0.02"/>
      </geometry>
    </collision>
  </link>

  <gazebo reference="bottom_link">
    <material>Gazebo/White</material>
  </gazebo>

  <!-- Bottom Joint -->
  <joint name = "bottom_joint" type = "fixed">
    <parent link = "bottom_link"/>
    <child link = "base_link"/>
    <origin xyz = "0 0 0" rpy = "0 0 0"/>
  </joint>

  <!-- Base Link  -->
  <link name = "base_link">
    <visual>
      <origin xyz = "0 0 0.07" rpy = "1.570795 0 0"/>
      <geometry>
        <box size = "0.1 0.1 0.1"/>
      </geometry>
      <material name = "White"/>
    </visual>

    <collision>
      <origin xyz = "0 0 0.07" rpy = "1.570795 0 0"/>
      <geometry>
        <box size = "0.1 0.1 0.1"/>
      </geometry>
    </collision>
    <inertial>
      <mass value="1"/>
      <inertia ixx="1.0" ixy="0.0" ixz="0.0" iyy="0.5" iyz="0.0" izz="1.0"/>
    </inertial>
  </link>

  <gazebo reference="base_link">
    <material>Gazebo/White</material>
  </gazebo>

  <!-- Shoulder Pan Joint -->
  <joint name = "shoulder_pan_joint" type = "revolute">
    <parent link = "base_link"/>
    <child link = "shoulder_pan_link"/>
    <origin xyz = "0 0 0.12" rpy = "0 1.570795 0"/>
    <axis xyz = "-1 0 0"/>
    <limit effort = "300" lower = "-2.61799387799" upper="1.98394848567" velocity="1"/>
    <dynamics damping = "50" friction = "1"/>
  </joint>

  <!-- Shoulder Pan Link  -->
  <link name = "shoulder_pan_link">
    <visual>
      <origin xyz = "0 0 0" rpy = "0 1.570795 0"/>
      <geometry>
        <cylinder length = "0.08" radius = "0.04"/>
      </geometry>
      <material name = "Red"/>
    </visual>

    <collision>
      <origin xyz = "0 0 0" rpy = "0 1.570795 0"/>
      <geometry>
        <cylinder length = "0.08" radius = "0.04"/>
      </geometry>
    </collision>
    <inertial>
      <mass value="1"/>
      <inertia ixx="1.0" ixy="0.0" ixz="0.0" iyy="0.5" iyz="0.0" izz="1.0"/>
    </inertial>
  </link>

  <gazebo reference="shoulder_pan_link">
    <material>Gazebo/Red</material>
  </gazebo>

  <!-- Shoulder Pitch Joint -->
  <joint name = "shoulder_pitch_joint" type = "revolute">
    <parent link = "shoulder_pan_link"/>
    <child link = "shoulder_pitch_link"/>
    <origin xyz = "-0.041 0.0021 0.0" rpy = "-1.570795 0 1.570795"/>
    <axis xyz = "1 0 0"/>
    <limit effort = "300" lower = "-1.19962513147" upper="1.89994105047" velocity="1"/>
    <dynamics damping = "50" friction = "1"/>
  </joint>

  <!-- Shoulder Pitch Link  -->
  <link name = "shoulder_pitch_link">
    <visual>
      <origin xyz = "-0.002 0 0.04" rpy = "0 1.570795 0"/>
      <geometry>
        <box size = "0.14 0.04 0.04"/>
      </geometry>
      <material name = "White"/>
    </visual>

    <collision>
      <origin xyz = "-0.002 0 0.04" rpy = "0 1.570795 0"/>
      <geometry>
        <box size = "0.14 0.04 0.04"/>
      </geometry>
    </collision>

    <inertial>
       <mass value="1"/>
       <inertia ixx="1.0" ixy="0.0" ixz="0.0" iyy="0.5" iyz="0.0" izz="1.0"/>
     </inertial>
  </link>

  <gazebo reference="shoulder_pitch_link">
    <material>Gazebo/Red</material>
  </gazebo>

  <!-- Elobow Roll Joint -->
  <joint name = "elbow_roll_joint" type = "revolute">
    <parent link = "shoulder_pitch_link"/>
    <child link = "elbow_roll_link"/>
    <origin xyz = "-0.002 0.0 0.1206" rpy = "3.14159 1.570795 0"/>
    <axis xyz = "-1 0 0"/>
    <limit effort = "300" lower = "-2.61799387799" upper="0.705631162427" velocity="1"/>
    <dynamics damping = "50" friction = "1"/>
  </joint>

  <!-- Elobow Roll Link  -->
  <link name = "elbow_roll_link">
    <visual>
      <origin xyz = "-0.015 0 0.0" rpy = "0 1.570795 0"/>
      <geometry>
        <cylinder length = "0.06" radius = "0.02"/>
      </geometry>
      <material name = "Black"/>
    </visual>

    <collision>
      <origin xyz = "-0.015 0 0.0" rpy = "0 1.570795 0"/>
      <geometry>
        <cylinder length = "0.06" radius = "0.02"/>
      </geometry>
    </collision>

    <inertial>
       <mass value="1"/>
       <inertia ixx="1.0" ixy="0.0" ixz="0.0" iyy="0.5" iyz="0.0" izz="1.0"/>
     </inertial>
  </link>

  <gazebo reference="elbow_roll_link">
    <material>Gazebo/Red</material>
  </gazebo>

  <!-- Elobow Pitch Joint -->
  <joint name = "elbow_pitch_joint" type = "revolute">
    <parent link = "elbow_roll_link"/>
    <child link = "elbow_pitch_link"/>
    <origin xyz = "-0.035 0.0 0.0" rpy = "0.055 1.570795 0"/>
    <axis xyz = "1 0 0"/>
    <limit effort = "300" lower = "-1.5953400194" upper= "1.93281579274" velocity="1"/>
    <dynamics damping = "50" friction = "1"/>
  </joint>

  <!-- Elobow Pitch Link  -->
  <link name = "elbow_pitch_link">
    <visual>
      <origin xyz = "0 0 -0.12" rpy = "0 1.570795 0"/>
      <geometry>
        <box size = "0.22 0.04 0.04"/>
      </geometry>
      <material name = "Red"/>
    </visual>

    <collision>
      <origin xyz = "0 0 -0.12" rpy = "0 1.570795 0"/>
      <geometry>
        <box size = "0.22 0.04 0.04"/>
      </geometry>
    </collision>

    <inertial>
       <mass value="1"/>
       <inertia ixx="1.0" ixy="0.0" ixz="0.0" iyy="0.5" iyz="0.0" izz="1.0"/>
     </inertial>
  </link>

  <gazebo reference="elbow_pitch_link">
    <material>Gazebo/Red</material>
  </gazebo>

  <!-- Wrist Roll Joint -->
  <joint name = "wrist_roll_joint" type = "revolute">
    <parent link = "elbow_pitch_link"/>
    <child link = "wrist_roll_link"/>
    <origin xyz = "0.0 0.0 -0.248" rpy = "0 1.570795 3.14159"/>
    <axis xyz = "1 0 0"/>
    <limit effort = "300" lower = "-2.61799387799" upper= "2.6128806087" velocity="1"/>
    <dynamics damping = "50" friction = "1"/>
  </joint>

  <!-- Wrist Roll Link  -->
  <link name = "wrist_roll_link">
    <visual>
      <origin xyz = "0 0 0" rpy = "0 1.570795 0"/>
      <geometry>
        <cylinder length = "0.06" radius = "0.02"/>
      </geometry>
      <material name = "Black"/>
    </visual>

    <collision>
      <origin xyz = "0 0 0" rpy = "0 1.570795 0"/>
      <geometry>
        <cylinder length = "0.06" radius = "0.02"/>
      </geometry>
    </collision>

    <inertial>
       <mass value="1"/>
       <inertia ixx="1.0" ixy="0.0" ixz="0.0" iyy="0.5" iyz="0.0" izz="1.0"/>
     </inertial>
  </link>

  <gazebo reference="wrist_roll_link">
    <material>Gazebo/Black</material>
  </gazebo>

  <!-- Wrist pitch Joint -->
  <joint name="wrist_pitch_joint" type="revolute">
     <parent link="wrist_roll_link"/>
     <child link="wrist_pitch_link"/>
     <origin xyz = "0.0 0.0 0.0" rpy = "0 1.570795 0"/>
     <axis xyz="1 0 0"/>
     <limit effort="300" lower="-1.5953400194" upper="1.98394848567" velocity="1"/>
     <dynamics damping="50" friction="1"/>
   </joint>

  <!-- Wrist Pitch Link -->
  <link name="wrist_pitch_link">
    <visual>
      <origin xyz="0 0 0.04" rpy="0 1.570795 0"/>
      <geometry>
        <box size="0.06 0.04 0.04"/>
      </geometry>
      <material name="White"/>
    </visual>
    <collision>
      <origin xyz="0 0 0.04 " rpy="0 1.570795 0"/>
      <geometry>
        <box size="0.06 0.04 0.04"/>
      </geometry>
    </collision>
    <inertial>
      <mass value="1"/>
      <inertia ixx="1.0" ixy="0.0" ixz="0.0" iyy="0.5" iyz="0.0" izz="1.0"/>
    </inertial>
  </link>

  <gazebo reference="wrist_pitch_link">
    <material>Gazebo/White</material>
  </gazebo>

  <!-- Gripper Roll Joint -->
  <joint name = "gripper_roll_joint" type = "revolute">
    <parent link = "wrist_pitch_link"/>
    <child link = "gripper_roll_link"/>
    <origin xyz = "0 0 0.08" rpy = "4.712385 -1.570795 0"/>
    <axis xyz = "1 0 0"/>
    <limit effort = "300" lower = "-2.61799387799" upper = "2.61799387799" velocity = "1"/>
    <dynamics damping = "50" friction = "1"/>
  </joint>

  <!-- Gripper Pitch Link -->
  <link name="gripper_roll_link">
    <visual>
      <origin xyz="0 0 0" rpy="0 1.570795 0"/>
      <geometry>
        <cylinder length = "0.02" radius = "0.04"/>
      </geometry>
      <material name="Red"/>
    </visual>
    <collision>
      <origin xyz="0 0 0 " rpy="0 1.570795 0"/>
      <geometry>
        <cylinder length = "0.02" radius = "0.04"/>
      </geometry>
    </collision>
    <inertial>
      <mass value="1"/>
      <inertia ixx="1.0" ixy="0.0" ixz="0.0" iyy="0.5" iyz="0.0" izz="1.0"/>
    </inertial>
  </link>

  <gazebo reference="gripper_roll_link">
    <material>Gazebo/Red</material>
  </gazebo>

  <!-- Finger Joint 1 -->
  <joint name = "finger_joint1" type = "prismatic">
    <parent link = "gripper_roll_link"/>
    <child link = "gripper_finger_link1"/>
    <origin xyz = "0 0 0"/>
    <axis xyz = "0 1 0"/>
    <limit effort = "1" lower = "0" upper = "0.03" velocity = "1.0"/>
    <!--<safety_controller k_position = "20" k_velocity = "20" soft_lower_limit = "-0.15" soft_upper_limit = "0.0"/>-->
    <dynamics damping = "50" friction = "1"/>
  </joint>

  <!-- Gripper Finger Link 1 -->
  <link name="gripper_finger_link1">
    <visual>
      <origin xyz="0.04 -0.03 0"/>
      <geometry>
        <box size="0.08 0.01 0.01"/>
      </geometry>
      <material name="White"/>
    </visual>
    <collision>
      <origin xyz="0.04 -0.03 0 "/>
      <geometry>
        <box size="0.08 0.01 0.01"/>
      </geometry>
    </collision>
    <inertial>
      <mass value="1"/>
      <inertia ixx="1.0" ixy="0.0" ixz="0.0" iyy="0.5" iyz="0.0" izz="1.0"/>
    </inertial>
  </link>

  <gazebo reference="gripper_finger_link1">
    <material>Gazebo/White</material>
  </gazebo>

  <!-- Finger Joint 2 -->
  <joint name = "finger_joint2" type = "prismatic">
    <parent link = "gripper_roll_link"/>
    <child link = "gripper_finger_link2"/>
    <origin xyz = "0 0 0"/>
    <axis xyz = "0 1 0"/>
    <limit effort = "1" lower = "-0.03" upper = "0" velocity = "1.0"/>
    <!--<safety_controller k_position = "20" k_velocity = "20" soft_lower_limit = "-0.15" soft_upper_limit = "0.0"/> -->
    <dynamics damping = "50" friction = "1"/>
  </joint>

  <!-- Gripper Finger Link 2 -->
  <link name="gripper_finger_link2">
    <visual>
      <origin xyz="0.04 0.03 0"/>
      <geometry>
        <box size="0.08 0.01 0.01"/>
      </geometry>
      <material name="White"/>
    </visual>
    <collision>
      <origin xyz="0.04 0.03 0 "/>
      <geometry>
        <box size="0.08 0.01 0.01"/>
      </geometry>
    </collision>
    <inertial>
      <mass value="1"/>
      <inertia ixx="1.0" ixy="0.0" ixz="0.0" iyy="0.5" iyz="0.0" izz="1.0"/>
    </inertial>
  </link>

  <gazebo reference="gripper_finger_link2">
    <material>Gazebo/White</material>
  </gazebo>

</robot>
